# 10. Eunit/Gen_server
## Задание \#1
При использовании варианта запуска тестов с foreach и входным параметром "#{name := Name}" в функциях, столкнулся с такой проблемой:
```erlang
2> c(keylist_srv_test).
{ok,keylist_srv_test}
3> eunit:test(keylist_srv_test).
undefined
*** test module not found ***
**ok

=======================================================
  Failed: 0.  Skipped: 0.  Passed: 0.
One or more tests were cancelled.
error
```
Причем, если использовать нулевую арность и константу имени модуля c foreach, то все проходит успешно.
```erlang
1> c(keylist_srv_test).
{ok,keylist_srv_test}
2> eunit:test(keylist_srv_test).
  All 5 tests passed.
ok
```
Поэтому оставил так:)

## Задание \#3
Запустите keylist_mgr\
Запустите keylist1, keylist2, keylist3\
Завершите keylist1 - exit(PidKeylist1, NotNormalReason)\
Проверьте и прокомментируйте что стало с вашими процессами Eshell, keylist_mgr, keylist2, keylist3
```erlang
Eshell V14.1 (press Ctrl+G to abort, type help(). for help)
1> c(keylist_srv).
keylist_srv.erl:12:2: Warning: undefined callback function handle_cast/2 (behaviour 'gen_server')
%   12| -behavior(gen_server).
%     |  ^

{ok,keylist_srv}
2> c(keylist_mgr).
{ok,keylist_mgr}
3> rr("keylist_srv.erl").
[stateChild]
4> rr("keylist_mgr.erl").
[state]
5> keylist_mgr:start_monitor().
Monitor Process Init: {ok,{<0.103.0>,#Ref<0.1325529685.3202351109.21398>}}
6> keylist_mgr:start_child(keylist1, permanent).
Process Init:
{ok,<0.105.0>}
7> keylist_mgr:start_child(keylist2, temporary).
Process Init:
Received added_new_child message. Pid: <0.107.0>, Name: keylist2
{ok,<0.107.0>}
8> keylist_mgr:start_child(keylist3, permanent).
Process Init:
Received added_new_child message. Pid: <0.109.0>, Name: keylist3
Received added_new_child message. Pid: <0.109.0>, Name: keylist3
{ok,<0.109.0>}

9> exit(whereis(keylist1), not_normal_reason).
Proc <0.105.0> terminating reason: {function_clause,
                                    [{keylist_srv,handle_info,
                                      [{'EXIT',<0.85.0>,not_normal_reason},
                                       {stateChild,[],0}],
                                      [{file,"keylist_srv.erl"},{line,123}]},
                                     {gen_server,try_handle_info,3,
                                      [{file,"gen_server.erl"},{line,1077}]},
                                     {gen_server,handle_msg,6,
                                      [{file,"gen_server.erl"},{line,1165}]},
                                     {proc_lib,init_p_do_apply,3,
                                      [{file,"proc_lib.erl"},{line,241}]}]} in state: {stateChild,
                                                                                       [],
                                                                                       0}
true
=ERROR REPORT==== 4-Dec-2023::05:30:35.083000 ===
** Generic server keylist1 terminating
** Last message in was {'EXIT',<0.85.0>,not_normal_reason}
** When Server state == {stateChild,[],0}
** Reason for termination ==
** {function_clause,[{keylist_srv,handle_info,
                                  [{'EXIT',<0.85.0>,not_normal_reason},
                                   {stateChild,[],0}],
                                  [{file,"keylist_srv.erl"},{line,123}]},
                     {gen_server,try_handle_info,3,
                                 [{file,"gen_server.erl"},{line,1077}]},
                     {gen_server,handle_msg,6,
                                 [{file,"gen_server.erl"},{line,1165}]},
                     {proc_lib,init_p_do_apply,3,
                               [{file,"proc_lib.erl"},{line,241}]}]}

=CRASH REPORT==== 4-Dec-2023::05:30:35.084000 ===
  crasher:
    initial call: keylist_srv:init/1
    pid: <0.105.0>
    registered_name: keylist1
    exception error: no function clause matching
                     keylist_srv:handle_info({'EXIT',<0.85.0>,
                                              not_normal_reason},
                                             {stateChild,[],0}) (keylist_srv.erl, line 123)
      in function  gen_server:try_handle_info/3 (gen_server.erl, line 1077)
      in call from gen_server:handle_msg/6 (gen_server.erl, line 1165)
    ancestors: [keylist_mgr,<0.85.0>,<0.84.0>,<0.70.0>,<0.65.0>,<0.69.0>,
                  <0.64.0>,kernel_sup,<0.47.0>]
    message_queue_len: 0
    messages: []
    links: [<0.103.0>]
    dictionary: []
    trap_exit: true
    status: running
    heap_size: 4185
    stack_size: 28
    reductions: 6240
  neighbours:

Process Init:
=ERROR REPORT==== 4-Dec-2023::05:30:35.096000 ===

Process keylist1 failed with reason: {function_clause,
                                      [{keylist_srv,handle_info,
                                        [{'EXIT',<0.85.0>,not_normal_reason},
                                         {stateChild,[],0}],
                                        [{file,"keylist_srv.erl"},{line,123}]},
                                       {gen_server,try_handle_info,3,
                                        [{file,"gen_server.erl"},{line,1077}]},
                                       {gen_server,handle_msg,6,
                                        [{file,"gen_server.erl"},{line,1165}]},
                                       {proc_lib,init_p_do_apply,3,
                                        [{file,"proc_lib.erl"},{line,241}]}]}

New Pid permanent process: <0.112.0>
Received added_new_child message. Pid: <0.112.0>, Name: keylist1
Received added_new_child message. Pid: <0.112.0>, Name: keylist1
Received added_new_child message. Pid: <0.112.0>, Name: keylist1

10>i().
<0.85.0>              erlang:apply/2                        6772    87098    0
c:pinfo/1                               50
<0.103.0>             keylist_mgr:init/1                    2586     7352    0
keylist_mgr           gen_server:loop/7                       11
<0.107.0>             keylist_srv:init/1                     233      149    0
keylist2              gen_server:loop/7                       11
<0.109.0>             keylist_srv:init/1                     233      102    0
keylist3              gen_server:loop/7                       11
<0.112.0>             keylist_srv:init/1                     233      102    0
keylist1              gen_server:loop/7                       11
Total                                                      66498   474337    0
390
ok

11> exit(whereis(keylist2), not_normal_reason).
Proc <0.107.0> terminating reason: {function_clause,
[{keylist_srv,handle_info,
[{'EXIT',<0.85.0>,not_normal_reason},
{stateChild,[],0}],
[{file,"keylist_srv.erl"},{line,123}]},
{gen_server,try_handle_info,3,
[{file,"gen_server.erl"},{line,1077}]},
{gen_server,handle_msg,6,
[{file,"gen_server.erl"},{line,1165}]},
{proc_lib,init_p_do_apply,3,
[{file,"proc_lib.erl"},{line,241}]}]} in state: {stateChild,
[],
0}
true
=ERROR REPORT==== 4-Dec-2023::05:38:42.030000 ===
** Generic server keylist2 terminating
** Last message in was {'EXIT',<0.85.0>,not_normal_reason}
** When Server state == {stateChild,[],0}
** Reason for termination ==
** {function_clause,[{keylist_srv,handle_info,
[{'EXIT',<0.85.0>,not_normal_reason},
{stateChild,[],0}],
[{file,"keylist_srv.erl"},{line,123}]},
{gen_server,try_handle_info,3,
[{file,"gen_server.erl"},{line,1077}]},
{gen_server,handle_msg,6,
[{file,"gen_server.erl"},{line,1165}]},
{proc_lib,init_p_do_apply,3,
[{file,"proc_lib.erl"},{line,241}]}]}

Received added_new_child message. Pid: <0.107.0>, Name: keylist2
Received added_new_child message. Pid: <0.107.0>, Name: keylist2
=CRASH REPORT==== 4-Dec-2023::05:38:42.030000 ===
crasher:
initial call: keylist_srv:init/1
pid: <0.107.0>
registered_name: keylist2
exception error: no function clause matching
keylist_srv:handle_info({'EXIT',<0.85.0>,
not_normal_reason},
{stateChild,[],0}) (keylist_srv.erl, line 123)
in function  gen_server:try_handle_info/3 (gen_server.erl, line 1077)
in call from gen_server:handle_msg/6 (gen_server.erl, line 1165)
ancestors: [keylist_mgr,<0.85.0>,<0.84.0>,<0.70.0>,<0.65.0>,<0.69.0>,
<0.64.0>,kernel_sup,<0.47.0>]
message_queue_len: 0
messages: []
links: [<0.103.0>]
dictionary: []
trap_exit: true
status: running
heap_size: 4185
stack_size: 28
reductions: 6270
neighbours:

=ERROR REPORT==== 4-Dec-2023::05:38:42.031000 ===

Process keylist2 failed with reason: {function_clause,
[{keylist_srv,handle_info,
[{'EXIT',<0.85.0>,not_normal_reason},
{stateChild,[],0}],
[{file,"keylist_srv.erl"},{line,123}]},
{gen_server,try_handle_info,3,
[{file,"gen_server.erl"},{line,1077}]},
{gen_server,handle_msg,6,
[{file,"gen_server.erl"},{line,1165}]},
{proc_lib,init_p_do_apply,3,
[{file,"proc_lib.erl"},{line,241}]}]}
```
Со всеми процессами, кроме keylist1, ничего не произошло. Так как keylist1 стартовал с параметром permanent, то после завершения 
он перезапустился и ему был назначен новый Pid.
При завершении child-процесса наши остальные слинкованные процессы должны остаться рабочими(при условии включенного флага), что и демонстрируется в Eshell.
Также, я решил проверить случай, когда завершаю keylist2 процесс с той же причиной, который является temporary.
Появились логи о его завершении, т.е., с остальными все в порядке, сам keylist2 успешно завершился.

—-----------------------\
Добавьте в любой keylist handle_call timer:sleep(10000).

Запустите keylist_mgr\
Запустите keylist1, keylist2\
Вызовите keylist:add(Name, Key, Value, Comment)\

У вас должен случиться exception.\
Проверьте и прокомментируйте, что стало с вашими процессами Eshell, keylist_mgr, keylist1, keylist2
Как бы мы могли это исправить(Без удаления timer:sleep(10000))? Изменить дефолтное значение Timeout?  

```erlang
Eshell V14.1 (press Ctrl+G to abort, type help(). for help)
1> c(keylist_srv).
keylist_srv.erl:12:2: Warning: undefined callback function handle_cast/2 (behaviour 'gen_server')
%   12| -behavior(gen_server).
%     |  ^

{ok,keylist_srv}
2> c(keylist_mgr).
{ok,keylist_mgr}
3> rr("keylist_srv.erl").
[stateChild]
4> rr("keylist_mgr.erl").
[state]
5> keylist_mgr:start_monitor().
Monitor Process Init: {ok,{<0.103.0>,#Ref<0.2431057287.1204027400.132264>}}
6> keylist_mgr:start_child(keylist1, permanent).
Process Init:
{ok,<0.105.0>}
7> keylist_mgr:start_child(keylist2, temporary).
Process Init:
Received added_new_child message. Pid: <0.107.0>, Name: keylist2
{ok,<0.107.0>}
8> keylist_srv:add(keylist1, key, 5, "Comm").
Added new element: {key,5,"Comm"}
** exception exit: {timeout,{gen_server,call,[keylist1,{add,key,5,"Comm"}]}}
     in function  gen_server:call/2 (gen_server.erl, line 386)
9>i().
<0.103.0>             keylist_mgr:init/1                     376      190    0
keylist_mgr           gen_server:loop/7                       11
<0.105.0>             keylist_srv:init/1                     233      153    0
keylist1              gen_server:loop/7                       11
<0.107.0>             keylist_srv:init/1                     233       61    0
keylist2              gen_server:loop/7                       11
<0.109.0>             erlang:apply/2                        1598    44731    0
c:pinfo/1                               50
Total                                                      44724   422046    0
379
ok
```
Случился exception по причине того, что в handle_call дефолтное время ожидания 5000 мс.
После добавления таймера на 10 сек, handle_call не дождался ответа и процесс Eshell завершился по причине timeout.
Остальные процессы продолжили работу, так как они только мониторились процессом eshell.

Исправить ситуацию мы можем путем добавления еще одного параметра в вызове, либо прописать в коде.
В нашем случае, для проверки можно использовать infinity, что будет значить бесконечное ожидание.

—-----------------------\
Добавьте в любой keylist handle_call 1/0 (деление на 0).

Запустите keylist_mgr\
Запустите keylist1, keylist2\
Вызовите keylist:add(Name, Key, Value, Comment)\

У вас должен случиться exception.\
Проверьте и прокомментируйте, что стало с вашими процессами Eshell, keylist_mgr, keylist1, keylist2
Как бы мы могли это исправить(Без удаления 1/0)? try/catch? 
```erlang
C:\Users\79642\Desktop\Erlang Eltex\eltex-erlang-homework\hw-11>erl
Erlang/OTP 26 [erts-14.1] [source] [64-bit] [smp:8:8] [ds:8:8:10] [async-threads:1] [jit:ns]

Eshell V14.1 (press Ctrl+G to abort, type help(). for help)
1> c(keylist_srv).
keylist_srv.erl:12:2: Warning: undefined callback function handle_cast/2 (behaviour 'gen_server')
%   12| -behavior(gen_server).
%     |  ^

keylist_srv.erl:79:4: Warning: evaluation of operator '/'/2 will fail with a 'badarith' exception
%   79|   1/0,
%     |    ^

keylist_srv.erl:79:4: Warning: the result of evaluating operator '/'/2 is ignored (suppress the warning by assigning the expression to the _ variable)
%   79|   1/0,
%     |    ^

{ok,keylist_srv}
2> c(keylist_mgr).
{ok,keylist_mgr}
3> rr("keylist_srv.erl").
[stateChild]
4> rr("keylist_mgr.erl").
[state]
5> keylist_mgr:start_monitor().
Monitor Process Init: {ok,{<0.103.0>,#Ref<0.3728734663.428343297.260108>}}
6> keylist_mgr:start_child(keylist1, permanent).
Process Init:
{ok,<0.105.0>}
7> keylist_mgr:start_child(keylist2, temporary).
Process Init:
Received added_new_child message. Pid: <0.107.0>, Name: keylist2
{ok,<0.107.0>}
8> keylist_srv:add(keylist1, key, 5, "Comment").
Added new element: {key,5,"Comment"}
Proc <0.105.0> terminating reason: {badarith,
                                    [{keylist_srv,handle_call,3,
                                      [{file,"keylist_srv.erl"},{line,79}]},
                                     {gen_server,try_handle_call,4,
                                      [{file,"gen_server.erl"},{line,1113}]},
                                     {gen_server,handle_msg,6,
                                      [{file,"gen_server.erl"},{line,1142}]},
                                     {proc_lib,init_p_do_apply,3,
                                      [{file,"proc_lib.erl"},{line,241}]}]} in state: {stateChild,
                                                                                       [],
                                                                                       0}
=ERROR REPORT==== 5-Dec-2023::00:46:11.526000 ===
** Generic server keylist1 terminating
** Last message in was {add,key,5,"Comment"}
** When Server state == {stateChild,[],0}
** Reason for termination ==
** {badarith,[{keylist_srv,handle_call,3,[{file,"keylist_srv.erl"},{line,79}]},
              {gen_server,try_handle_call,4,
                          [{file,"gen_server.erl"},{line,1113}]},
              {gen_server,handle_msg,6,[{file,"gen_server.erl"},{line,1142}]},
              {proc_lib,init_p_do_apply,3,
                        [{file,"proc_lib.erl"},{line,241}]}]}
** Client <0.85.0> stacktrace
** [{gen,do_call,4,[{file,"gen.erl"},{line,259}]},
    {gen_server,call,2,[{file,"gen_server.erl"},{line,382}]},
    {erl_eval,do_apply,7,[{file,"erl_eval.erl"},{line,750}]},
    {shell,exprs,7,[{file,"shell.erl"},{line,782}]},
    {shell,eval_exprs,7,[{file,"shell.erl"},{line,738}]},
    {shell,eval_loop,4,[{file,"shell.erl"},{line,723}]}]

=CRASH REPORT==== 5-Dec-2023::00:46:11.527000 ===
  crasher:
    initial call: keylist_srv:init/1
    pid: <0.105.0>
    registered_name: keylist1
    exception error: an error occurred when evaluating an arithmetic expression
      in function  keylist_srv:handle_call/3 (keylist_srv.erl, line 79)
      in call from gen_server:try_handle_call/4 (gen_server.erl, line 1113)
      in call from gen_server:handle_msg/6 (gen_server.erl, line 1142)
    ancestors: [keylist_mgr,<0.85.0>,<0.84.0>,<0.70.0>,<0.65.0>,<0.69.0>,
                  <0.64.0>,kernel_sup,<0.47.0>]
    message_queue_len: 0
    messages: []
    links: [<0.103.0>]
    dictionary: []
    trap_exit: true
    status: running
    heap_size: 6772
    stack_size: 28
    reductions: 9428
  neighbours:

Process Init:
=ERROR REPORT==== 5-Dec-2023::00:46:11.531000 ===

Process keylist1 failed with reason: {badarith,
                                      [{keylist_srv,handle_call,3,
                                        [{file,"keylist_srv.erl"},{line,79}]},
                                       {gen_server,try_handle_call,4,
                                        [{file,"gen_server.erl"},{line,1113}]},
                                       {gen_server,handle_msg,6,
                                        [{file,"gen_server.erl"},{line,1142}]},
                                       {proc_lib,init_p_do_apply,3,
                                        [{file,"proc_lib.erl"},{line,241}]}]}

** exception exit: {{badarith,[{keylist_srv,handle_call,3,
                                            [{file,"keylist_srv.erl"},{line,79}]},
                               {gen_server,try_handle_call,4,
                                           [{file,"gen_server.erl"},{line,1113}]},
                               {gen_server,handle_msg,6,
                                           [{file,"gen_server.erl"},{line,1142}]},
                               {proc_lib,init_p_do_apply,3,
                                         [{file,"proc_lib.erl"},{line,241}]}]},
                    {gen_server,call,[keylist1,{add,key,5,"Comment"}]}}
     in function  gen_server:call/2 (gen_server.erl, line 386)
New Pid permanent process: <0.109.0>
Received added_new_child message. Pid: <0.109.0>, Name: keylist1
Received added_new_child message. Pid: <0.109.0>, Name: keylist1
9> i().
<0.103.0>             keylist_mgr:init/1                    2586     6354    0
keylist_mgr           gen_server:loop/7                       11
<0.107.0>             keylist_srv:init/1                     233      102    0
keylist2              gen_server:loop/7                       11
<0.109.0>             keylist_srv:init/1                     233      102    0
keylist1              gen_server:loop/7                       11
<0.110.0>             erlang:apply/2                        2586    44718    0
c:pinfo/1                               50
Total                                                      49898   464319    0
379
ok
```
Случился exception по причине арифметической ошибки. Eshell упал(переназначился новый Pid), keylist1 упал и перезапустился,
keylist2 и keylist_mgr продолжили работу. Почти все то же самое, что и в предыдущем примере(отличается только причина падения).
Если обойтись без удаления "1/0", то нужно использовать конструкцию try/catch, чтобы поймать такой случай.
